#VRML_SIM R2023b utf8

EXTERNPROTO "https://raw.githubusercontent.com/cyberbotics/webots/R2023b/projects/objects/backgrounds/protos/TexturedBackground.proto"
EXTERNPROTO "https://raw.githubusercontent.com/cyberbotics/webots/R2023b/projects/objects/backgrounds/protos/TexturedBackgroundLight.proto"
EXTERNPROTO "https://raw.githubusercontent.com/cyberbotics/webots/R2023b/projects/objects/floors/protos/RectangleArena.proto"

WorldInfo {
}
Viewpoint {
  orientation -0.06877674224240574 0.05158348713158842 0.9962975979002793 1.5311524349983592
  position 0.24963832672180794 -0.8767609028621993 0.2957784831069103
}
TexturedBackground {
}
TexturedBackgroundLight {
}
RectangleArena {
}
Robot {
  translation 0 0 0.2
  children [
    HingeJoint {
      jointParameters HingeJointParameters {
        axis 0 0 1
      }
      device [
        PositionSensor {
          name "positionSensor1"
        }
        DEF MOTOR_1 RotationalMotor {
          name "rotationalMotor1"
        }
      ]
      endPoint Solid {
        translation 0.06 0 0
        rotation 1 0 0 1.5708
        children [
          HingeJoint {
            jointParameters HingeJointParameters {
              axis 0 0 1
            }
            device [
              PositionSensor {
                name "positionSensor2"
              }
              RotationalMotor {
                name "rotationalMotor2"
              }
            ]
            endPoint Solid {
              translation 0.06 0 0
              rotation -0.9999999999999999 0 0 1.5707953071795862
              children [
                CadShape {
                  url [
                    "../protos/meshes/lx16a_servo_socket.dae"
                  ]
                }
                HingeJoint {
                  jointParameters HingeJointParameters {
                    axis 0 0 1
                  }
                  device [
                    PositionSensor {
                      name "positionSensor3"
                    }
                    RotationalMotor {
                      name "rotationalMotor3"
                    }
                  ]
                  endPoint Solid {
                    translation 0.06 0 0
                    rotation 1 0 0 1.5708
                    children [
                      CadShape {
                        url [
                          "../protos/meshes/lx16a_servo_socket.dae"
                        ]
                      }
                      HingeJoint {
                        jointParameters HingeJointParameters {
                          axis 0 0 1
                        }
                        device [
                          PositionSensor {
                            name "positionSensor4"
                          }
                          RotationalMotor {
                            name "rotationalMotor4"
                          }
                        ]
                        endPoint Solid {
                          translation 0.06 0 0
                          rotation -0.9999999999999999 0 0 1.5707953071795862
                          children [
                            CadShape {
                              url [
                                "../protos/meshes/lx16a_servo_socket.dae"
                              ]
                            }
                            HingeJoint {
                              jointParameters HingeJointParameters {
                                axis 0 0 1
                              }
                              device [
                                PositionSensor {
                                  name "positionSensor5"
                                }
                                RotationalMotor {
                                  name "rotationalMotor5"
                                }
                              ]
                              endPoint Solid {
                                translation 0.06 0 0
                                rotation 1 0 0 1.5708
                                children [
                                  CadShape {
                                    url [
                                      "../protos/meshes/lx16a_servo_socket.dae"
                                    ]
                                  }
                                  HingeJoint {
                                    jointParameters HingeJointParameters {
                                      axis 0 0 1
                                    }
                                    device [
                                      PositionSensor {
                                        name "positionSensor6"
                                      }
                                      RotationalMotor {
                                        name "rotationalMotor6"
                                      }
                                    ]
                                    endPoint Solid {
                                      translation 0.06 0 0
                                      rotation 0.9999999999999999 0 0 1.5707953071795862
                                      children [
                                        CadShape {
                                          url [
                                            "../protos/meshes/lx16a_servo_socket.dae"
                                          ]
                                        }
                                        HingeJoint {
                                          jointParameters HingeJointParameters {
                                            axis 0 0 1
                                          }
                                          device [
                                            PositionSensor {
                                              name "positionSensor7"
                                            }
                                            RotationalMotor {
                                              name "rotationalMotor7"
                                            }
                                          ]
                                          endPoint DEF END_EFFECTOR Solid {
                                            translation 0.026 0 0
                                            rotation -0.9999999999999999 0 0 1.5707953071795862
                                            children [
                                              CadShape {
                                                url [
                                                  "../protos/meshes/lx16a_socket.dae"
                                                ]
                                              }
                                            ]
                                            boundingObject Pose {
                                              translation -0.01 0 0
                                              children [
                                                Box {
                                                  size 0.025 0.045 0.025
                                                }
                                              ]
                                            }
                                            physics Physics {
                                            }
                                          }
                                        }
                                      ]
                                      boundingObject DEF SERVO_BOUND Pose {
                                        translation -0.012 0 0
                                        children [
                                          Box {
                                            size 0.05 0.03 0.04
                                          }
                                        ]
                                      }
                                      physics DEF SERVO_PHYSICS Physics {
                                      }
                                    }
                                  }
                                ]
                                boundingObject USE SERVO_BOUND
                                physics USE SERVO_PHYSICS
                              }
                            }
                          ]
                          boundingObject USE SERVO_BOUND
                          physics USE SERVO_PHYSICS
                        }
                      }
                    ]
                    boundingObject USE SERVO_BOUND
                    physics USE SERVO_PHYSICS
                  }
                }
              ]
              boundingObject USE SERVO_BOUND
              physics USE SERVO_PHYSICS
            }
          }
          CadShape {
            url [
              "../protos/meshes/lx16a_servo_socket.dae"
            ]
          }
        ]
        boundingObject USE SERVO_BOUND
        physics USE SERVO_PHYSICS
      }
    }
    CadShape {
      url [
        "../protos/meshes/lx16a_servo.dae"
      ]
    }
  ]
  name "Snake"
  controller "<extern>"
  supervisor TRUE
}
