#VRML_SIM R2022b utf8
# license: Apache License 2.0
# license url: http://www.apache.org/licenses/LICENSE-2.0
# Denso VP6242 6 dof robotic arm.

PROTO DensoVP6242 [
    field SFVec3f       translation     0 0 0
    field SFRotation    rotation        0 0 1 0
    field SFString      controller      "<generic>"
    field SFString      name            "Denso VP6242"
    field SFNode        handExtension   NULL
]
{
    Robot {
        translation IS translation
        rotation IS rotation
        controller IS controller
        name IS name
        children [
            CadShape {
                url [
                    "meshes/visual/link0.dae"
                ]
            }
            HingeJoint {
                jointParameters HingeJointParameters {
                    axis 0 0 1
                    anchor 0 0 0.1550
                }
                device [
                    RotationalMotor {
                        name "joint1"
                    }
                ]
                endPoint Solid {
                    translation 0 0 0.1550
                    children [
                        CadShape {
                            url [
                                "meshes/visual/link1.dae"
                            ]
                        }
                        HingeJoint {
                            jointParameters HingeJointParameters {
                                axis 0 -1 0
                                anchor 0 0 0.1250
                            }
                            device [
                                RotationalMotor {
                                    name "joint2"
                                }
                            ]
                            endPoint Solid {
                                translation 0 0 0.1250
                                rotation 0.5773 -0.5773 0.5773 2.0944
                                children [
                                    CadShape {
                                        url [
                                            "meshes/visual/link2.dae"
                                        ]
                                    }
                                    HingeJoint {
                                        jointParameters HingeJointParameters {
                                            axis 0 0 1
                                            anchor 0.2100 0 0
                                        }
                                        device [
                                            RotationalMotor {
                                                name "joint3"
                                            }
                                        ]
                                        endPoint Solid {
                                            translation 0.2100 0 0
                                            rotation 0 0 -1 1.5707
                                            children [
                                                CadShape {
                                                    url [
                                                        "meshes/visual/link3.dae"
                                                    ]
                                                }
                                                HingeJoint {
                                                    jointParameters HingeJointParameters {
                                                        anchor 0.08 0.0750 0
                                                    }
                                                    device [
                                                        RotationalMotor {
                                                            name "joint4"
                                                        }
                                                    ]
                                                    endPoint Solid {
                                                        translation 0.0800 0.0750 0
                                                        rotation -0.5773 0.5773 -0.5773 2.0944
                                                        children [
                                                            CadShape {
                                                                url [
                                                                    "meshes/visual/link4.dae"
                                                                ]
                                                            }
                                                            HingeJoint {
                                                                jointParameters HingeJointParameters {
                                                                    axis 0 -1 0
                                                                    anchor 0 0 0.1300
                                                                }
                                                                device [
                                                                    RotationalMotor {
                                                                        name "joint5"
                                                                    }
                                                                ]
                                                                endPoint Solid {
                                                                    translation 0 0 0.13
                                                                    rotation 1 0 0 1.5707
                                                                    children [
                                                                        CadShape {
                                                                            url [
                                                                                "meshes/visual/link5.dae"
                                                                            ]
                                                                        }
                                                                        HingeJoint {
                                                                            jointParameters HingeJointParameters {
                                                                                axis 0 1 0
                                                                                anchor 0 0.0700 0
                                                                            }
                                                                            device [
                                                                                RotationalMotor {
                                                                                    name "joint6"
                                                                                }
                                                                            ]
                                                                            endPoint Solid {
                                                                                translation 0 0.07 0
                                                                                rotation -1 0 0 1.5707
                                                                                children [
                                                                                    CadShape {
                                                                                        url [
                                                                                            "meshes/visual/link6.dae"
                                                                                        ]
                                                                                    }
                                                                                    Slot {
                                                                                        type "robotHand"
                                                                                        endPoint IS handExtension
                                                                                    }
                                                                                ]
                                                                            }
                                                                        }
                                                                    ]
                                                                }
                                                            }
                                                        ]
                                                    }
                                                }
                                            ]
                                        }
                                    }
                                ]
                            }
                        }
                    ]
                }
            }
        ]
    }
}