<?xml version="1.0" ?>
<!-- =================================================================================== -->
<!-- |    This document was autogenerated by xacro from snakesim/resource/snake_robot.xacro | -->
<!-- |    EDITING THIS FILE BY HAND IS NOT RECOMMENDED                                 | -->
<!-- =================================================================================== -->
<robot name="Snake5R">
  <link name="link0">
    <visual>
      <!--origin xyz="-0.0127 0 0.2" rpy="0 0 0"/-->
      <origin rpy="0 -1.5707 0" xyz="0 0 0"/>
      <geometry>
        <box size="0.0451 0.0247 0.034"/>
      </geometry>
    </visual>
  </link>
  <joint name="rotationalMotor1" type="continuous">
    <parent link="link0"/>
    <child link="link1"/>
    <axis xyz="0 0 1"/>
    <origin rpy="0 -1.5707 0" xyz="0 0 0.0127"/>
    <!--origin xyz="0 0 0.2" rpy="0 0 0"/-->
    <limit effort="10" lower="-2.0943" upper="2.0943" velocity="10"/>
  </joint>
  <link name="link1">
    <visual>
      <origin rpy="0 0 0" xyz="0.047 0 0"/>
      <geometry>
        <box size="0.0451 0.0247 0.034"/>
      </geometry>
    </visual>
    <visual>
      <origin rpy="0 0 0" xyz="0.02 0 0"/>
      <geometry>
        <box size="0.01 0.042 0.046"/>
      </geometry>
    </visual>
    <visual>
      <origin rpy="0 0 0" xyz="0.004 0 -0.02"/>
      <geometry>
        <box size="0.022 0.02 0.007"/>
      </geometry>
    </visual>
    <visual>
      <origin rpy="0 0 0" xyz="0.004 0 0.02"/>
      <geometry>
        <box size="0.022 0.02 0.007"/>
      </geometry>
    </visual>
  </link>
  <joint name="rotationalMotor2" type="continuous">
    <parent link="link1"/>
    <child link="link2"/>
    <axis xyz="0 0 1"/>
    <origin rpy="1.5707 0 0" xyz="0.06 0 0"/>
    <limit effort="10" lower="-2.0943" upper="2.0943" velocity="10"/>
  </joint>
  <link name="link2">
    <visual>
      <origin rpy="0 0 0" xyz="0.047 0 0"/>
      <geometry>
        <box size="0.0451 0.0247 0.034"/>
      </geometry>
    </visual>
    <visual>
      <origin rpy="0 0 0" xyz="0.02 0 0"/>
      <geometry>
        <box size="0.01 0.042 0.046"/>
      </geometry>
    </visual>
    <visual>
      <origin rpy="0 0 0" xyz="0.004 0 -0.02"/>
      <geometry>
        <box size="0.022 0.02 0.007"/>
      </geometry>
    </visual>
    <visual>
      <origin rpy="0 0 0" xyz="0.004 0 0.02"/>
      <geometry>
        <box size="0.022 0.02 0.007"/>
      </geometry>
    </visual>
  </link>
  <joint name="rotationalMotor3" type="continuous">
    <parent link="link2"/>
    <child link="link3"/>
    <axis xyz="0 0 1"/>
    <origin rpy="-1.5707 0 0" xyz="0.06 0 0"/>
    <limit effort="10" lower="-2.0943" upper="2.0943" velocity="10"/>
  </joint>
  <link name="link3">
    <visual>
      <origin rpy="0 0 0" xyz="0.047 0 0"/>
      <geometry>
        <box size="0.0451 0.0247 0.034"/>
      </geometry>
    </visual>
    <visual>
      <origin rpy="0 0 0" xyz="0.02 0 0"/>
      <geometry>
        <box size="0.01 0.042 0.046"/>
      </geometry>
    </visual>
    <visual>
      <origin rpy="0 0 0" xyz="0.004 0 -0.02"/>
      <geometry>
        <box size="0.022 0.02 0.007"/>
      </geometry>
    </visual>
    <visual>
      <origin rpy="0 0 0" xyz="0.004 0 0.02"/>
      <geometry>
        <box size="0.022 0.02 0.007"/>
      </geometry>
    </visual>
  </link>
  <joint name="rotationalMotor4" type="continuous">
    <parent link="link3"/>
    <child link="link4"/>
    <axis xyz="0 0 1"/>
    <origin rpy="1.5707 0 0" xyz="0.06 0 0"/>
    <limit effort="10" lower="-2.0943" upper="2.0943" velocity="10"/>
  </joint>
  <link name="link4">
    <visual>
      <origin rpy="0 0 0" xyz="0.047 0 0"/>
      <geometry>
        <box size="0.0451 0.0247 0.034"/>
      </geometry>
    </visual>
    <visual>
      <origin rpy="0 0 0" xyz="0.02 0 0"/>
      <geometry>
        <box size="0.01 0.042 0.046"/>
      </geometry>
    </visual>
    <visual>
      <origin rpy="0 0 0" xyz="0.004 0 -0.02"/>
      <geometry>
        <box size="0.022 0.02 0.007"/>
      </geometry>
    </visual>
    <visual>
      <origin rpy="0 0 0" xyz="0.004 0 0.02"/>
      <geometry>
        <box size="0.022 0.02 0.007"/>
      </geometry>
    </visual>
  </link>
  <joint name="rotationalMotor5" type="continuous">
    <parent link="link4"/>
    <child link="link5"/>
    <axis xyz="0 0 1"/>
    <origin rpy="-1.5707 0 0" xyz="0.06 0 0"/>
    <limit effort="10" lower="-2.0943" upper="2.0943" velocity="10"/>
  </joint>
  <link name="link5">
    <visual>
      <origin rpy="0 0 0" xyz="0.02 0 0"/>
      <geometry>
        <box size="0.01 0.042 0.046"/>
      </geometry>
    </visual>
    <visual>
      <origin rpy="0 0 0" xyz="0.004 0 -0.02"/>
      <geometry>
        <box size="0.022 0.02 0.007"/>
      </geometry>
    </visual>
    <visual>
      <origin rpy="0 0 0" xyz="0.004 0 0.02"/>
      <geometry>
        <box size="0.022 0.02 0.007"/>
      </geometry>
    </visual>
  </link>
  <joint name="endEffFrame" type="fixed">
    <parent link="link5"/>
    <child link="endEffector"/>
    <axis xyz="0 0 1"/>
    <origin rpy="0 0 0" xyz="0.02 0 0"/>
  </joint>
  <link name="endEffector"/>
</robot>
