#VRML_SIM R2023b utf8

EXTERNPROTO "https://raw.githubusercontent.com/cyberbotics/webots/R2023a/projects/objects/backgrounds/protos/TexturedBackground.proto"
EXTERNPROTO "https://raw.githubusercontent.com/cyberbotics/webots/R2023a/projects/objects/backgrounds/protos/TexturedBackgroundLight.proto"
EXTERNPROTO "https://raw.githubusercontent.com/cyberbotics/webots/R2023a/projects/objects/floors/protos/RectangleArena.proto"
EXTERNPROTO "https://raw.githubusercontent.com/cyberbotics/webots/R2023a/projects/appearances/protos/Parquetry.proto"

WorldInfo {
}
Viewpoint {
  orientation -0.03808991637022693 -0.0034057231755079058 0.9992685121230235 3.29885297148819
  position 1.5618600426639528 0.6091824929565739 0.4950024583141214
}
TexturedBackground {
  texture "empty_office"
}
TexturedBackgroundLight {
}
RectangleArena {
  floorSize 5 5
  floorAppearance Parquetry {
  }
}
Robot {
  children [
    CadShape {
      url [
        "/home/hgtllys/ros2_ws/src/yamor_control/protos/meshes/visual/link0.dae"
      ]
    }
    HingeJoint {
      jointParameters HingeJointParameters {
        axis 0 0 1
        anchor 0 0 0.155
        minStop -2.7925
        maxStop 2.7925
      }
      device [
        PositionSensor {
          name "positionSensor1"
        }
        RotationalMotor {
          name "rotationalMotor1"
          maxTorque 100
        }
      ]
      endPoint Solid {
        translation 0 0 0.155
        children [
          CadShape {
            url [
              "/home/hgtllys/ros2_ws/src/yamor_control/protos/meshes/visual/link1.dae"
            ]
          }
          HingeJoint {
            jointParameters HingeJointParameters {
              axis 0 -1 0
              anchor 0 0 0.125
              minStop -2.0944
              maxStop 2.0944
            }
            device [
              PositionSensor {
                name "positionSensor2"
              }
              RotationalMotor {
                name "rotationalMotor2"
                maxTorque 100
              }
            ]
            endPoint Solid {
              translation 0 0 0.125
              rotation 0.5773502691896258 -0.5773502691896258 0.5773502691896258 2.0944
              children [
                CadShape {
                  url [
                    "/home/hgtllys/ros2_ws/src/yamor_control/protos/meshes/visual/link2.dae"
                  ]
                }
                HingeJoint {
                  jointParameters HingeJointParameters {
                    axis 0 0 1
                    anchor 0.21 0 0
                    maxStop 2.7925
                  }
                  device [
                    PositionSensor {
                      name "positionSensor3"
                    }
                    RotationalMotor {
                      name "rotationalMotor3"
                      maxTorque 5
                    }
                  ]
                  endPoint Solid {
                    translation 0.21 0 0
                    rotation 0 0 -0.9999999999999999 1.5706999999999998
                    children [
                      CadShape {
                        url [
                          "/home/hgtllys/ros2_ws/src/yamor_control/protos/meshes/visual/link3.dae"
                        ]
                      }
                      HingeJoint {
                        jointParameters HingeJointParameters {
                          anchor 0.08 0.075 0
                          minStop -2.7925
                          maxStop 2.7925
                        }
                        device [
                          PositionSensor {
                            name "positionSensor4"
                          }
                          RotationalMotor {
                            name "rotationalMotor4"
                            maxTorque 100
                          }
                        ]
                        endPoint Solid {
                          translation 0.08 0.075 0
                          rotation -0.5773502691896258 0.5773502691896258 -0.5773502691896258 2.0944
                          children [
                            CadShape {
                              url [
                                "/home/hgtllys/ros2_ws/src/yamor_control/protos/meshes/visual/link4.dae"
                              ]
                            }
                            HingeJoint {
                              jointParameters HingeJointParameters {
                                axis 0 -1 0
                                anchor 0 0 0.13
                                minStop -2.0944
                                maxStop 2.0944
                              }
                              device [
                                PositionSensor {
                                  name "positionSensor5"
                                }
                                RotationalMotor {
                                  name "rotationalMotor5"
                                  maxTorque 100
                                }
                              ]
                              endPoint Solid {
                                translation 0 0 0.13
                                rotation 0.9999999999999999 0 0 1.5706999999999998
                                children [
                                  CadShape {
                                    url [
                                      "/home/hgtllys/ros2_ws/src/yamor_control/protos/meshes/visual/link5.dae"
                                    ]
                                  }
                                  HingeJoint {
                                    jointParameters HingeJointParameters {
                                      axis 0 1 0
                                      anchor 0 0.07 0
                                      minStop -3.1415
                                      maxStop 3.1415
                                    }
                                    device [
                                      PositionSensor {
                                        name "positionSensor6"
                                      }
                                      RotationalMotor {
                                        name "rotationalMotor6"
                                        maxTorque 100
                                      }
                                    ]
                                    endPoint Solid {
                                      translation 0 0.07 0
                                      rotation -0.9999999999999999 0 0 1.5706999999999998
                                      children [
                                        CadShape {
                                          url [
                                            "/home/hgtllys/ros2_ws/src/yamor_control/protos/meshes/visual/link6.dae"
                                          ]
                                        }
                                        Slot {
                                          type "robotHand"
                                        }
                                      ]
                                      boundingObject Pose {
                                        translation -2.42763e-08 1.05085e-08 -0.01
                                        rotation -1.73924e-06 -6.88391e-07 -1 -1.5707953071795862
                                        children [
                                          Cylinder {
                                            height 0.02
                                            radius 0.035
                                          }
                                        ]
                                      }
                                      physics Physics {
                                        density -1
                                        mass 0.0833
                                      }
                                    }
                                  }
                                ]
                                boundingObject Pose {
                                  rotation 0.5773489358556708 -0.5773509358554485 -0.5773509358554485 -2.094395307179586
                                  children [
                                    Cylinder {
                                      height 0.1
                                      radius 0.04
                                    }
                                  ]
                                }
                                physics Physics {
                                  density -1
                                  mass 0.544
                                }
                              }
                            }
                          ]
                          boundingObject Pose {
                            translation 4.24576e-07 0 0.08
                            rotation 0 -1 0 -5.307179586466759e-06
                            children [
                              Cylinder {
                                height 0.15
                                radius 0.055
                              }
                            ]
                          }
                          physics Physics {
                            density -1
                            mass 1.5427
                          }
                        }
                      }
                    ]
                    boundingObject Pose {
                      translation -6.74634e-14 0.075 -2.51033e-13
                      rotation 0 1 0 1.5708
                      children [
                        Cylinder {
                          height 0.2
                          radius 0.055
                        }
                      ]
                    }
                    physics Physics {
                      density -1
                      mass 2.0569
                    }
                  }
                }
              ]
              boundingObject Pose {
                translation 0.1 0 -3.6732e-07
                rotation 0 1 0 1.5708
                children [
                  Cylinder {
                    height 0.25
                    radius 0.09
                  }
                ]
              }
              physics Physics {
                density -1
                mass 7.5805
              }
            }
          }
        ]
        boundingObject Pose {
          translation 0 0 0.08
          children [
            Cylinder {
              height 0.17
              radius 0.09
            }
          ]
        }
        physics Physics {
          density -1
          mass 4.6816
        }
      }
    }
  ]
  name "Denso VP6242"
  boundingObject DEF BASE Group {
    children [
      Pose {
        translation -0.03 0 0.09
        children [
          Box {
            size 0.2 0.17 0.17
          }
        ]
      }
    ]
  }
}
